Workbook

Sheet CorST
A1: Слово | B1: Частота-CorST | C1: IPM-CorST | D1: Ранг-CorST | E1: Номер строки, на которой слово стоит в RLC | F1: IPM-RLC
A2: в | B2: 35889 | C2: 11520.564 | D2: =RANK(B2,$B:$B,0) -> 1 | E2: =MATCH(A2,RLC!$A:$A,0) -> 3 | F2: {=INDEX(RLC!$C:$C,E2)} -> 37993.234
A3: и | B3: 31435 | C3: 10090.806 | D3: =RANK(B3,$B:$B,0) -> 2 | E3: =MATCH(A3,RLC!$A:$A,0) -> 2 | F3: {=INDEX(RLC!$C:$C,E3)} -> 38334.702
A4: на | B4: 13212 | C4: 4241.1239 | D4: =RANK(B4,$B:$B,0) -> 3 | E4: =MATCH(A4,RLC!$A:$A,0) -> 5 | F4: {=INDEX(RLC!$C:$C,E4)} -> 13265.412
A5: не | B5: 11811 | C5: 3791.3953 | D5: =RANK(B5,$B:$B,0) -> 4 | E5: =MATCH(A5,RLC!$A:$A,0) -> 6 | F5: {=INDEX(RLC!$C:$C,E5)} -> 12860.168
A6: с | B6: 11363 | C6: 3647.5848 | D6: =RANK(B6,$B:$B,0) -> 5 | E6: =MATCH(A6,RLC!$A:$A,0) -> 8 | F6: {=INDEX(RLC!$C:$C,E6)} -> 9178.432
A7: что | B7: 10265 | C7: 3295.1208 | D7: =RANK(B7,$B:$B,0) -> 6 | E7: =MATCH(A7,RLC!$A:$A,0) -> 4 | F7: {=INDEX(RLC!$C:$C,E7)} -> 16305.402
A8: как | B8: 7396 | C8: 2374.1562 | D8: =RANK(B8,$B:$B,0) -> 7 | E8: =MATCH(A8,RLC!$A:$A,0) -> 9 | F8: {=INDEX(RLC!$C:$C,E8)} -> 8273.6097
A9: к | B9: 6790 | C9: 2179.6269 | D9: =RANK(B9,$B:$B,0) -> 8 | E9: =MATCH(A9,RLC!$A:$A,0) -> 15 | F9: {=INDEX(RLC!$C:$C,E9)} -> 4742.0127
A10: а | B10: 5924 | C10: 1901.6362 | D10: =RANK(B10,$B:$B,0) -> 9 | E10: =MATCH(A10,RLC!$A:$A,0) -> 20 | F10: {=INDEX(RLC!$C:$C,E10)} -> 3449.2197
A11: для | B11: 5652 | C11: 1814.3227 | D11: =RANK(B11,$B:$B,0) -> 10 | E11: =MATCH(A11,RLC!$A:$A,0) -> 14 | F11: {=INDEX(RLC!$C:$C,E11)} -> 5009.0748
A12: по | B12: 5634 | C12: 1808.5447 | D12: =RANK(B12,$B:$B,0) -> 11 | E12: =MATCH(A12,RLC!$A:$A,0) -> 16 | F12: {=INDEX(RLC!$C:$C,E12)} -> 4641.034
A13: о | B13: 4912 | C13: 1576.7787 | D13: =RANK(B13,$B:$B,0) -> 12 | E13: =MATCH(A13,RLC!$A:$A,0) -> 13 | F13: {=INDEX(RLC!$C:$C,E13)} -> 5022.3615
... A1349: форм | B1349: 92 | C1349: 29.532501 | D1349: =RANK(B1349,$B:$B,0) -> 1326 | E1349: =MATCH(A1349,RLC!$A:$A,0) -> 5289 | F1349: {=INDEX(RLC!$C:$C,E1349)} -> 21.258673
A1350: школе | B1350: 92 | C1350: 29.532501 | D1350: =RANK(B1350,$B:$B,0) -> 1326 | E1350: =MATCH(A1350,RLC!$A:$A,0) -> 404 | F1350: {=INDEX(RLC!$C:$C,E1350)} -> 259.09008 | G1350: =C1350>E1350 -> FALSE
A1351: элементов | B1351: 92 | C1351: 29.532501 | D1351: =RANK(B1351,$B:$B,0) -> 1326 | E1351: =MATCH(A1351,RLC!$A:$A,0) -> 4112 | F1351: {=INDEX(RLC!$C:$C,E1351)} -> 27.902008
A1352: этими | B1352: 92 | C1352: 29.532501 | D1352: =RANK(B1352,$B:$B,0) -> 1326 | E1352: =MATCH(A1352,RLC!$A:$A,0) -> 1492 | F1352: {=INDEX(RLC!$C:$C,E1352)} -> 77.062689
A1353: артикля | B1353: 91 | C1353: 29.211495 | D1353: =RANK(B1353,$B:$B,0) -> 1352 | E1353: =MATCH(A1353,RLC!$A:$A,0) -> #N/A | F1353: {=INDEX(RLC!$C:$C,E1353)} -> #N/A
A1354: всему | B1354: 91 | C1354: 29.211495 | D1354: =RANK(B1354,$B:$B,0) -> 1352 | E1354: =MATCH(A1354,RLC!$A:$A,0) -> 741 | F1354: {=INDEX(RLC!$C:$C,E1354)} -> 144.82471
A1355: выполнения | B1355: 91 | C1355: 29.211495 | D1355: =RANK(B1355,$B:$B,0) -> 1352 | E1355: =MATCH(A1355,RLC!$A:$A,0) -> #N/A | F1355: {=INDEX(RLC!$C:$C,E1355)} -> #N/A
A1356: достоевский | B1356: 91 | C1356: 29.211495 | D1356: =RANK(B1356,$B:$B,0) -> 1352 | E1356: =MATCH(A1356,RLC!$A:$A,0) -> #N/A | F1356: {=INDEX(RLC!$C:$C,E1356)} -> #N/A
A1357: менеджмента | B1357: 91 | C1357: 29.211495 | D1357: =RANK(B1357,$B:$B,0) -> 1352 | E1357: =MATCH(A1357,RLC!$A:$A,0) -> 2858 | F1357: {=INDEX(RLC!$C:$C,E1357)} -> 39.860012
A1358: наша | B1358: 91 | C1358: 29.211495 | D1358: =RANK(B1358,$B:$B,0) -> 1352 | E1358: =MATCH(A1358,RLC!$A:$A,0) -> 551 | F1358: {=INDEX(RLC!$C:$C,E1358)} -> 193.98539
A1359: поднятая | B1359: 91 | C1359: 29.211495 | D1359: =RANK(B1359,$B:$B,0) -> 1352 | E1359: =MATCH(A1359,RLC!$A:$A,0) -> #N/A | F1359: {=INDEX(RLC!$C:$C,E1359)} -> #N/A
A1360: постепенно | B1360: 91 | C1360: 29.211495 | D1360: =RANK(B1360,$B:$B,0) -> 1352 | E1360: =MATCH(A1360,RLC!$A:$A,0) -> 2469 | F1360: {=INDEX(RLC!$C:$C,E1360)} -> 46.503347
A1361: рублей | B1361: 91 | C1361: 29.211495 | D1361: =RANK(B1361,$B:$B,0) -> 1352 | E1361: =MATCH(A1361,RLC!$A:$A,0) -> 1697 | F1361: {=INDEX(RLC!$C:$C,E1361)} -> 67.76202
A1362: сегодняшний | B1362: 91 | C1362: 29.211495 | D1362: =RANK(B1362,$B:$B,0) -> 1352 | E1362: =MATCH(A1362,RLC!$A:$A,0) -> 1873 | F1362: {=INDEX(RLC!$C:$C,E1362)} -> 62.447352
... A1716: чехов | B1716: 73 | C1716: 23.433397 | D1716: =RANK(B1716,$B:$B,0) -> 1684 | E1716: =MATCH(A1716,RLC!$A:$A,0) -> #N/A | F1716: {=INDEX(RLC!$C:$C,E1716)} -> #N/A
A1717: шапочка | B1717: 73 | C1717: 23.433397 | D1717: =RANK(B1717,$B:$B,0) -> 1684 | E1717: =MATCH(A1717,RLC!$A:$A,0) -> 3340 | F1717: {=INDEX(RLC!$C:$C,E1717)} -> 34.545343 | G1717: =C1717>E1717 -> FALSE
A1718: широко | B1718: 73 | C1718: 23.433397 | D1718: =RANK(B1718,$B:$B,0) -> 1684 | E1718: =MATCH(A1718,RLC!$A:$A,0) -> 1585 | F1718: {=INDEX(RLC!$C:$C,E1718)} -> 73.076688 | G1718: =C1718>E1718 -> FALSE
A1719: эмоций | B1719: 73 | C1719: 23.433397 | D1719: =RANK(B1719,$B:$B,0) -> 1684 | E1719: =MATCH(A1719,RLC!$A:$A,0) -> 6913 | F1719: {=INDEX(RLC!$C:$C,E1719)} -> 15.944005
A1720: большие | B1720: 72 | C1720: 23.112392 | D1720: =RANK(B1720,$B:$B,0) -> 1719 | E1720: =MATCH(A1720,RLC!$A:$A,0) -> 837 | F1720: {=INDEX(RLC!$C:$C,E1720)} -> 128.8807
A1721: большого | B1721: 72 | C1721: 23.112392 | D1721: =RANK(B1721,$B:$B,0) -> 1719 | E1721: =MATCH(A1721,RLC!$A:$A,0) -> 2651 | F1721: {=INDEX(RLC!$C:$C,E1721)} -> 42.517346
A1722: ведет | B1722: 72 | C1722: 23.112392 | D1722: =RANK(B1722,$B:$B,0) -> 1719 | E1722: =MATCH(A1722,RLC!$A:$A,0) -> 3483 | F1722: {=INDEX(RLC!$C:$C,E1722)} -> 31.888009
A1723: вниз | B1723: 72 | C1723: 23.112392 | D1723: =RANK(B1723,$B:$B,0) -> 1719 | E1723: =MATCH(A1723,RLC!$A:$A,0) -> 2832 | F1723: {=INDEX(RLC!$C:$C,E1723)} -> 39.860012
A1724: вузов | B1724: 72 | C1724: 23.112392 | D1724: =RANK(B1724,$B:$B,0) -> 1719 | E1724: =MATCH(A1724,RLC!$A:$A,0) -> 6052 | F1724: {=INDEX(RLC!$C:$C,E1724)} -> 17.272672
A1725: выражений | B1725: 72 | C1725: 23.112392 | D1725: =RANK(B1725,$B:$B,0) -> 1719 | E1725: =MATCH(A1725,RLC!$A:$A,0) -> 3786 | F1725: {=INDEX(RLC!$C:$C,E1725)} -> 29.230675
A1726: гражданским | B1726: 72 | C1726: 23.112392 | D1726: =RANK(B1726,$B:$B,0) -> 1719 | E1726: =MATCH(A1726,RLC!$A:$A,0) -> #N/A | F1726: {=INDEX(RLC!$C:$C,E1726)} -> #N/A
A1727: изучить | B1727: 72 | C1727: 23.112392 | D1727: =RANK(B1727,$B:$B,0) -> 1719 | E1727: =MATCH(A1727,RLC!$A:$A,0) -> 4372 | F1727: {=INDEX(RLC!$C:$C,E1727)} -> 25.244674
A1728: ин | B1728: 72 | C1728: 23.112392 | D1728: =RANK(B1728,$B:$B,0) -> 1719 | E1728: =MATCH(A1728,RLC!$A:$A,0) -> #N/A | F1728: {=INDEX(RLC!$C:$C,E1728)} -> #N/A
...

Sheet RLC
A1: Слово | B1: Частота-RLC | C1: IPM-RLC | D1: Ранг-RLC | E1: Номер строки, на которой слово стоит в CorST
A2: и | B2: 28852 | C2: 38334.702 | D2: =RANK(B2,$B:$B,0) -> 1 | E2: =MATCH(A2,CorST!$A:$A,0) -> 3
A3: в | B3: 28595 | C3: 37993.234 | D3: =RANK(B3,$B:$B,0) -> 2 | E3: =MATCH(A3,CorST!$A:$A,0) -> 2
A4: что | B4: 12272 | C4: 16305.402 | D4: =RANK(B4,$B:$B,0) -> 3 | E4: =MATCH(A4,CorST!$A:$A,0) -> 7
A5: на | B5: 9984 | C5: 13265.412 | D5: =RANK(B5,$B:$B,0) -> 4 | E5: =MATCH(A5,CorST!$A:$A,0) -> 4
A6: не | B6: 9679 | C6: 12860.168 | D6: =RANK(B6,$B:$B,0) -> 5 | E6: =MATCH(A6,CorST!$A:$A,0) -> 5
A7: я | B7: 8489 | C7: 11279.055 | D7: =RANK(B7,$B:$B,0) -> 6 | E7: =MATCH(A7,CorST!$A:$A,0) -> 24
A8: с | B8: 6908 | C8: 9178.432 | D8: =RANK(B8,$B:$B,0) -> 7 | E8: =MATCH(A8,CorST!$A:$A,0) -> 6
A9: как | B9: 6227 | C9: 8273.6097 | D9: =RANK(B9,$B:$B,0) -> 8 | E9: =MATCH(A9,CorST!$A:$A,0) -> 8
A10: это | B10: 5389 | C10: 7160.1868 | D10: =RANK(B10,$B:$B,0) -> 9 | E10: =MATCH(A10,CorST!$A:$A,0) -> 15
A11: но | B11: 4307 | C11: 5722.569 | D11: =RANK(B11,$B:$B,0) -> 10 | E11: =MATCH(A11,CorST!$A:$A,0) -> 19
A12: он | B12: 4050 | C12: 5381.1016 | D12: =RANK(B12,$B:$B,0) -> 11 | E12: =MATCH(A12,CorST!$A:$A,0) -> 21
A13: о | B13: 3780 | C13: 5022.3615 | D13: =RANK(B13,$B:$B,0) -> 12 | E13: =MATCH(A13,CorST!$A:$A,0) -> 13
... A8127: японский | B8127: 10 | C8127: 13.286671 | D8127: =RANK(B8127,$B:$B,0) -> 7471 | E8127: =MATCH(A8127,CorST!$A:$A,0) -> 14067

Sheet merge
A1: Слово | B1: IPM-CorST | C1: IPM-RLC
A2: а | B2: 1901.6362 | C2: 3449.2197
A3: аббревиатуры | B3: 4.4940762
A4: абзац | B4: 86.029458 | C4: 75.734022
A5: абзаца | B5: 51.039865
A6: абзаце | B6: 43.014729 | C6: 23.916007
A7: абзацев | B7: 12.198207
A8: абзацу | B8: 3.5310598
A9: абзацы | B9: 43.65674
A10: абитуриентов | B10: 3.2100544 | C10: 27.902008
A11: абитуриенты | C11: 15.944005
A12: абрамова | B12: 3.2100544
A13: абсолютно | B13: 35.631604 | C13: 81.04869
A14: абсолютной | B14: 4.1730707
A15: абстрагироваться | B15: 5.4570925
A16: абстрактного | B16: 6.7411142
A17: абстрактное | B17: 13.803234
A18: абстрактном | B18: 3.5310598
A19: абстрактные | B19: 8.6671469 | C19: 14.615338
A20: абстрактный | B20: 4.1730707
A21: абстрактным | B21: 6.0991034
A22: абстрактными | B22: 3.2100544
A23: абстрактных | B23: 5.4570925
A24: абсурд | B24: 3.2100544
A25: абсурда | B25: 9.3091578 | C25: 13.286671
A26: авангард | C26: 14.615338
A27: авангарда | C27: 43.846013
A28: авангардистов | C28: 15.944005
A29: авангардные | C29: 15.944005
A30: аварии | C30: 38.531345
A31: авария | C31: 14.615338
A32: август | B32: 18.29731
A33: августа | B33: 25.680435 | C33: 57.132683
A34: августе | C34: 13.286671
A35: австрийский | B35: 6.4201088
A36: австрийского | B36: 5.4570925
A37: автобиографическое | B37: 4.8150816
A38: автобиография | B38: 3.2100544
A39: автобус | B39: 3.8520653 | C39: 14.615338
A40: автобусе | C40: 17.272672
...
